<?xml version="1.0" ?>
<!-- =================================================================================== -->
<!-- |    This document was autogenerated by xacro from bbbot_gazebo.xacro             | -->
<!-- |    EDITING THIS FILE BY HAND IS NOT RECOMMENDED                                 | -->
<!-- =================================================================================== -->
<!-- Revolute-Revolute Manipulator -->
<robot name="bbbot" xmlns:xacro="http://www.ros.org/wiki/xacro">
  <material name="black">
    <color rgba="0.0 0.0 0.0 1.0"/>
  </material>
  <material name="blue">
    <color rgba="0.0 0.0 0.8 1.0"/>
  </material>
  <material name="green">
    <color rgba="0.0 0.8 0.0 1.0"/>
  </material>
  <material name="grey">
    <color rgba="0.2 0.2 0.2 1.0"/>
  </material>
  <material name="orange">
    <color rgba="1.0 0.423529411765 0.0392156862745 1.0"/>
  </material>
  <material name="brown">
    <color rgba="0.870588235294 0.811764705882 0.764705882353 1.0"/>
  </material>
  <material name="red">
    <color rgba="0.8 0.0 0.0 1.0"/>
  </material>
  <material name="white">
    <color rgba="1.0 1.0 1.0 1.0"/>
  </material>
  <link name="world"/>
  <link name="base_link"/>
  <joint name="base_link__base_joint" type="fixed">
    <origin rpy="0 0 0" xyz="0 0 0"/>
    <parent link="base_link"/>
    <child link="stand_link"/>
  </joint>
  <link name="stand_link">
    <visual>
      <origin rpy="1.570796327 0 0" xyz="0 0 0"/>
      <geometry>
        <mesh filename="package://bbbot_description/meshes/visual/stand.stl"/>
        <!-- <mesh filename="package://bbbot_description/meshes/visual/stand_low.stl" /> -->
      </geometry>
      <material name="white"/>
    </visual>
    <collision>
      <origin rpy="0 0 0" xyz="0.3 0.3 0"/>
      <geometry>
        <mesh filename="package://bbbot_description/meshes/collision/stand.stl"/>
      </geometry>
    </collision>
    <inertial>
      <origin rpy="0 0 0" xyz="0 0 0"/>
      <mass value="1000"/>
      <inertia ixx="100.0" ixy="0.0" ixz="0.0" iyy="100.0" iyz="0.0" izz="100.0"/>
    </inertial>
  </link>
  <gazebo>
    <!-- <plugin name="${prefix_val}ros_control" filename="libgazebo_ros_control.so"> -->
    <plugin filename="libfilter_gazebo_ros_control.so" name="leftarm_ros_control">
      <robotNamespace>leftarm</robotNamespace>
      <filterJointsParam>joint_names</filterJointsParam>
      <robotSimType>gazebo_ros_control/DefaultRobotHWSim</robotSimType>
    </plugin>
  </gazebo>
  <gazebo>
    <!-- <plugin name="${prefix_val}ros_control" filename="libgazebo_ros_control.so"> -->
    <plugin filename="libfilter_gazebo_ros_control.so" name="rightarm_ros_control">
      <robotNamespace>rightarm</robotNamespace>
      <filterJointsParam>joint_names</filterJointsParam>
      <robotSimType>gazebo_ros_control/DefaultRobotHWSim</robotSimType>
    </plugin>
  </gazebo>
  <!-- First element of the arm fixed to the parent -->
  <joint name="world_leftarm__base_joint" type="fixed">
    <origin rpy="-1.570796327 -1.570796327 0" xyz="0.045 0.1665 1.526"/>
    <parent link="world"/>
    <child link="leftarm_shoulder_link"/>
  </joint>
  <!-- link 1 -->
  <link name="leftarm_shoulder_link">
    <collision>
      <origin rpy="0 0 3.141592654" xyz="0 0 0.063"/>
      <geometry>
        <box size="0.054 0.054 0.126"/>
      </geometry>
    </collision>
    <visual>
      <origin rpy="0 0 3.141592654" xyz="0 0 0"/>
      <geometry>
        <mesh filename="package://manipulator_description/meshes/link_1.stl" scale="0.001 0.001 0.001"/>
      </geometry>
      <material name="grey"/>
    </visual>
    <inertial>
      <!-- <origin xyz="0 0 0" rpy="0 0 0"/> -->
      <!-- <mass value="0.936"/> -->
      <!-- <inertia ixx="1.0" ixy="0.0" ixz="0.0" iyy="1.0" iyz="0.0" izz="1.0" /> -->
      <origin rpy="0 0 0" xyz="0.00023 0.00000 0.06223"/>
      <mass value="0.85644"/>
      <!-- <inertia ixx="0.00121064" ixy="0.0" ixz="0.00001100" iyy="0.00120886" iyz="0.0" izz="0.00038103" /> -->
      <inertia ixx="0.00134118504" ixy="0.0" ixz="0.0" iyy="0.00134118504" iyz="0.0" izz="0.00041622984"/>
    </inertial>
  </link>
  <!-- Joint 1 -->
  <joint name="leftarm_shoulder_pan_joint" type="revolute">
    <parent link="leftarm_shoulder_link"/>
    <child link="leftarm_upper_arm_link"/>
    <origin rpy="0 0 0" xyz="0 0 0.126"/>
    <axis xyz="0 0 1"/>
    <limit effort="1000" lower="-2.9845130213" upper="2.9845130213" velocity="6.5"/>
    <dynamics damping="0"/>
  </joint>
  <!-- link 2 -->
  <link name="leftarm_upper_arm_link">
    <collision>
      <origin rpy="0 0 3.141592654" xyz="0 0 0.03"/>
      <geometry>
        <box size="0.06 0.14 0.06"/>
      </geometry>
    </collision>
    <visual>
      <origin rpy="0 0 3.141592654" xyz="0 0 -0.126"/>
      <geometry>
        <mesh filename="package://manipulator_description/meshes/link_2.stl" scale="0.001 0.001 0.001"/>
      </geometry>
      <material name="grey"/>
    </visual>
    <inertial>
      <!-- <origin xyz="0 0 0" rpy="0 0 0"/> -->
      <!-- <mass value="1.030"/> -->
      <!-- <inertia ixx="1.0" ixy="0.0" ixz="0.0" iyy="1.0" iyz="0.0" izz="1.0" /> -->
      <origin rpy="0 0 0" xyz="0.00000 0.00080 0.03183"/>
      <mass value="0.94658"/>
      <!-- <inertia ixx="0.00152547" ixy="0.0" ixz="0.0" iyy="0.00045954" iyz="-0.00001086" izz="0.00151740" /> -->
      <inertia ixx="0.00183005466667" ixy="0.0" ixz="0.0" iyy="0.000567948" iyz="0.0" izz="0.00183005466667"/>
    </inertial>
  </link>
  <!-- Joint 2 -->
  <joint name="leftarm_shoulder_lift_joint" type="revolute">
    <parent link="leftarm_upper_arm_link"/>
    <child link="leftarm_forearm_link"/>
    <origin rpy="0 0 0" xyz="0 0 0.033"/>
    <axis xyz="0 1 0"/>
    <limit effort="1000" lower="-1.8849555924" upper="1.8849555924" velocity="6.5"/>
    <dynamics damping="0"/>
  </joint>
  <!-- link 3 -->
  <link name="leftarm_forearm_link">
    <collision>
      <origin rpy="1.570796327 0 3.141592654" xyz="-.001 0 0.148"/>
      <geometry>
        <mesh filename="package://manipulator_description/meshes/collision/link3.stl"/>
      </geometry>
    </collision>
    <visual>
      <origin rpy="0 0 3.141592654" xyz="0 0 -0.159"/>
      <geometry>
        <mesh filename="package://manipulator_description/meshes/link_3.stl" scale="0.001 0.001 0.001"/>
      </geometry>
      <material name="grey"/>
    </visual>
    <inertial>
      <origin rpy="0 0 0" xyz="0 0 0.148"/>
      <!-- <mass value="1.404"/> -->
      <!-- <inertia ixx="1.0" ixy="0.0" ixz="0.0" iyy="1.0" iyz="0.0" izz="1.0" /> -->
      <mass value="1.30260"/>
      <!-- <inertia ixx="0.01111021" ixy="0.00001331" ixz="-0.00134208" iyy="0.01046642" iyz="0.00016235" izz="0.00202081" /> -->
      <inertia ixx="0.0136625102365" ixy="0.0" ixz="0.0" iyy="0.0124082569044" iyz="0.0" izz="0.00324753226791"/>
    </inertial>
  </link>
  <!-- Joint 3 -->
  <joint name="leftarm_elbow_joint" type="revolute">
    <parent link="leftarm_forearm_link"/>
    <child link="leftarm_wrist_1_link"/>
    <origin rpy="0 0.7853981635 0" xyz="0.03 0.0 0.264"/>
    <axis xyz="0 1 0"/>
    <limit effort="1000" lower="-1.2566370616" upper="2.26194671088" velocity="6.5"/>
    <dynamics damping="0"/>
  </joint>
  <!-- link 4 -->
  <link name="leftarm_wrist_1_link">
    <collision>
      <origin rpy="1.570796327 0 3.141592654" xyz="-0.03 0.0 0.1285"/>
      <geometry>
        <mesh filename="package://manipulator_description/meshes/collision/link4.stl"/>
      </geometry>
    </collision>
    <visual>
      <origin rpy="0 0 3.141592654" xyz="-0.03 0 -0.423"/>
      <geometry>
        <mesh filename="package://manipulator_description/meshes/link_4.stl" scale="0.001 0.001 0.001"/>
      </geometry>
      <material name="grey"/>
    </visual>
    <inertial>
      <origin rpy="0 1.570796327 0" xyz="-0.03 0 0.1285"/>
      <!-- <mass value="1.236" /> -->
      <!-- <inertia ixx="1.0" ixy="0.0" ixz="0.0" iyy="1.0" iyz="0.0" izz="1.0" /> -->
      <mass value="1.15977"/>
      <!-- <inertia ixx="0.00096726" ixy="0.00004383" ixz="-0.00002771" iyy="0.00318801" iyz="0.00000627" izz="0.00341484" /> -->
      <inertia ixx="0.00205032491251" ixy="0.0" ixz="0.0" iyy="0.00691847164616" iyz="0.0" izz="0.00765159473365"/>
    </inertial>
  </link>
  <!-- Joint 4 -->
  <joint name="leftarm_wrist_1_joint" type="revolute">
    <parent link="leftarm_wrist_1_link"/>
    <child link="leftarm_wrist_2_link"/>
    <origin rpy="0 0 0" xyz="-0.03 0.0 0.231"/>
    <axis xyz="0 0 1"/>
    <limit effort="1000" lower="-3.141592654" upper="3.141592654" velocity="6.5"/>
    <dynamics damping="0"/>
  </joint>
  <!-- link 5 -->
  <link name="leftarm_wrist_2_link">
    <collision>
      <origin rpy="0 0 3.141592654" xyz="0.0 0.0 0.024"/>
      <geometry>
        <box size="0.048 0.09 0.048"/>
      </geometry>
    </collision>
    <visual>
      <origin rpy="0 0 3.141592654" xyz="0 0 -0.654"/>
      <geometry>
        <mesh filename="package://manipulator_description/meshes/link_5.stl" scale="0.001 0.001 0.001"/>
      </geometry>
      <material name="grey"/>
    </visual>
    <inertial>
      <origin rpy="0 0 0" xyz="0 0 0.024"/>
      <!-- <mass value="0.491" /> -->
      <!-- <inertia ixx="1.0" ixy="0.0" ixz="0.0" iyy="1.0" iyz="0.0" izz="1.0" /> -->
      <mass value="0.44688"/>
      <!-- <inertia ixx="0.00030285" ixy="0.00000761" ixz="0.00000031" iyy="0.00022339" iyz="-0.00000001" izz="0.00039766" /> -->
      <inertia ixx="0.00038744496" ixy="0.0" ixz="0.0" iyy="0.00017160192" iyz="0.0" izz="0.00038744496"/>
    </inertial>
  </link>
  <!-- Joint 5 -->
  <joint name="leftarm_wrist_2_joint" type="revolute">
    <parent link="leftarm_wrist_2_link"/>
    <child link="leftarm_wrist_3_link"/>
    <origin rpy="0 0 0" xyz="0.0 0.0 0.027"/>
    <axis xyz="0 1 0"/>
    <limit effort="1000" lower="-1.570796327" upper="1.570796327" velocity="6.5"/>
    <dynamics damping="0"/>
  </joint>
  <!-- link 6 -->
  <link name="leftarm_wrist_3_link">
    <collision>
      <origin rpy="1.570796327 0 1.570796327" xyz="0.0 0.0 0.081"/>
      <geometry>
        <mesh filename="package://manipulator_description/meshes/collision/link6.stl"/>
      </geometry>
    </collision>
    <visual>
      <origin rpy="0 0 3.141592654" xyz="0 0 -0.681"/>
      <geometry>
        <mesh filename="package://manipulator_description/meshes/link_6.stl" scale="0.001 0.001 0.001"/>
      </geometry>
      <material name="grey"/>
    </visual>
    <inertial>
      <origin rpy="1.570796327 1.570796327 0" xyz="0 0 0.081"/>
      <!-- <mass value="0.454" /> -->
      <!-- <inertia ixx="1.0" ixy="0.0" ixz="0.0" iyy="1.0" iyz="0.0" izz="1.0" /> -->
      <mass value="0.43273"/>
      <!-- <inertia ixx="0.00021512" ixy="0.00001009" ixz="0.00000000" iyy="0.00042827" iyz="0.00000000" izz="0.00051436" /> -->
      <inertia ixx="0.00039594795" ixy="0.0" ixz="0.0" iyy="0.00104401581334" iyz="0.0" izz="0.000775290483338"/>
    </inertial>
  </link>
  <!-- Joint 6 -->
  <joint name="leftarm_wrist_3_joint" type="revolute">
    <parent link="leftarm_wrist_3_link"/>
    <child link="leftarm_ee_link"/>
    <origin rpy="0 0 0" xyz="0.0 0.0 0.123"/>
    <axis xyz="0 0 1"/>
    <limit effort="1000" lower="-3.141592654" upper="3.141592654" velocity="6.5"/>
    <dynamics damping="0"/>
  </joint>
  <!-- End Effector -->
  <link name="leftarm_ee_link">
  </link>
  <transmission name="leftarm_shoulder_pan_trans">
    <type>transmission_interface/SimpleTransmission</type>
    <joint name="leftarm_shoulder_pan_joint">
      <hardwareInterface>EffortJointInterface</hardwareInterface>
    </joint>
    <actuator name="leftarm_shoulder_pan_motor">
      <hardwareInterface>EffortJointInterface</hardwareInterface>
      <mechanicalReduction>1</mechanicalReduction>
    </actuator>
  </transmission>
  <transmission name="leftarm_shoulder_lift_trans">
    <type>transmission_interface/SimpleTransmission</type>
    <joint name="leftarm_shoulder_lift_joint">
      <hardwareInterface>EffortJointInterface</hardwareInterface>
    </joint>
    <actuator name="leftarm_shoulder_lift_motor">
      <hardwareInterface>EffortJointInterface</hardwareInterface>
      <mechanicalReduction>1</mechanicalReduction>
    </actuator>
  </transmission>
  <transmission name="leftarm_elbow_trans">
    <type>transmission_interface/SimpleTransmission</type>
    <joint name="leftarm_elbow_joint">
      <hardwareInterface>EffortJointInterface</hardwareInterface>
    </joint>
    <actuator name="leftarm_elbow_motor">
      <hardwareInterface>EffortJointInterface</hardwareInterface>
      <mechanicalReduction>1</mechanicalReduction>
    </actuator>
  </transmission>
  <transmission name="leftarm_wrist_1_trans">
    <type>transmission_interface/SimpleTransmission</type>
    <joint name="leftarm_wrist_1_joint">
      <hardwareInterface>EffortJointInterface</hardwareInterface>
    </joint>
    <actuator name="leftarm_wrist_1_motor">
      <hardwareInterface>EffortJointInterface</hardwareInterface>
      <mechanicalReduction>1</mechanicalReduction>
    </actuator>
  </transmission>
  <transmission name="leftarm_wrist_2_trans">
    <type>transmission_interface/SimpleTransmission</type>
    <joint name="leftarm_wrist_2_joint">
      <hardwareInterface>EffortJointInterface</hardwareInterface>
    </joint>
    <actuator name="leftarm_wrist_2_motor">
      <hardwareInterface>EffortJointInterface</hardwareInterface>
      <mechanicalReduction>1</mechanicalReduction>
    </actuator>
  </transmission>
  <transmission name="leftarm_wrist_3_trans">
    <type>transmission_interface/SimpleTransmission</type>
    <joint name="leftarm_wrist_3_joint">
      <hardwareInterface>EffortJointInterface</hardwareInterface>
    </joint>
    <actuator name="leftarm_wrist_3_motor">
      <hardwareInterface>EffortJointInterface</hardwareInterface>
      <mechanicalReduction>1</mechanicalReduction>
    </actuator>
  </transmission>
  <joint name="leftarm_ee_link_leftarm_base_joint" type="fixed">
    <origin rpy="0 0 1.570796327" xyz="0 0 0"/>
    <parent link="leftarm_ee_link"/>
    <child link="leftarm_finger_link"/>
  </joint>
  <link name="leftarm_finger_link">
    <visual>
      <origin rpy="1.570796327 0 0" xyz="0 0 0"/>
      <geometry>
        <mesh filename="package://bbbot_description/meshes/visual/finger.stl"/>
      </geometry>
      <material name="white"/>
    </visual>
    <!-- Need better collision model -->
    <collision>
      <origin rpy="1.570796327 0 1.570796327" xyz="0 0 0"/>
      <geometry>
        <mesh filename="package://bbbot_description/meshes/collision/finger.stl"/>
      </geometry>
      <!-- <origin xyz="0 0 0" rpy="${pi/2} 0 0"/>
        <geometry>
          <mesh filename="package://bbbot_description/meshes/visual/finger.stl" />
        </geometry> -->
    </collision>
    <!-- <inertial>
        <origin xyz="0 0 0" rpy="0 0 0"/>
        <mass value="0.250"/>
        <inertia ixx="0.0" ixy="0.0" ixz="0.0" iyy="0.0" iyz="0.0" izz="0.0"/>
      </inertial> -->
    <inertial>
      <origin rpy="0 0 0" xyz="0 0 0.05"/>
      <mass value="0.3"/>
      <inertia ixx="0.0008125" ixy="0" ixz="0" iyy="0.001125" iyz="0" izz="0.001125"/>
    </inertial>
  </link>
  <!-- First element of the arm fixed to the parent -->
  <joint name="world_rightarm__base_joint" type="fixed">
    <origin rpy="1.570796327 -1.570796327 0" xyz="0.045 -0.1665 1.526"/>
    <parent link="world"/>
    <child link="rightarm_shoulder_link"/>
  </joint>
  <!-- link 1 -->
  <link name="rightarm_shoulder_link">
    <collision>
      <origin rpy="0 0 3.141592654" xyz="0 0 0.063"/>
      <geometry>
        <box size="0.054 0.054 0.126"/>
      </geometry>
    </collision>
    <visual>
      <origin rpy="0 0 3.141592654" xyz="0 0 0"/>
      <geometry>
        <mesh filename="package://manipulator_description/meshes/link_1.stl" scale="0.001 0.001 0.001"/>
      </geometry>
      <material name="grey"/>
    </visual>
    <inertial>
      <!-- <origin xyz="0 0 0" rpy="0 0 0"/> -->
      <!-- <mass value="0.936"/> -->
      <!-- <inertia ixx="1.0" ixy="0.0" ixz="0.0" iyy="1.0" iyz="0.0" izz="1.0" /> -->
      <origin rpy="0 0 0" xyz="0.00023 0.00000 0.06223"/>
      <mass value="0.85644"/>
      <!-- <inertia ixx="0.00121064" ixy="0.0" ixz="0.00001100" iyy="0.00120886" iyz="0.0" izz="0.00038103" /> -->
      <inertia ixx="0.00134118504" ixy="0.0" ixz="0.0" iyy="0.00134118504" iyz="0.0" izz="0.00041622984"/>
    </inertial>
  </link>
  <!-- Joint 1 -->
  <joint name="rightarm_shoulder_pan_joint" type="revolute">
    <parent link="rightarm_shoulder_link"/>
    <child link="rightarm_upper_arm_link"/>
    <origin rpy="0 0 0" xyz="0 0 0.126"/>
    <axis xyz="0 0 1"/>
    <limit effort="1000" lower="-2.9845130213" upper="2.9845130213" velocity="6.5"/>
    <dynamics damping="0"/>
  </joint>
  <!-- link 2 -->
  <link name="rightarm_upper_arm_link">
    <collision>
      <origin rpy="0 0 3.141592654" xyz="0 0 0.03"/>
      <geometry>
        <box size="0.06 0.14 0.06"/>
      </geometry>
    </collision>
    <visual>
      <origin rpy="0 0 3.141592654" xyz="0 0 -0.126"/>
      <geometry>
        <mesh filename="package://manipulator_description/meshes/link_2.stl" scale="0.001 0.001 0.001"/>
      </geometry>
      <material name="grey"/>
    </visual>
    <inertial>
      <!-- <origin xyz="0 0 0" rpy="0 0 0"/> -->
      <!-- <mass value="1.030"/> -->
      <!-- <inertia ixx="1.0" ixy="0.0" ixz="0.0" iyy="1.0" iyz="0.0" izz="1.0" /> -->
      <origin rpy="0 0 0" xyz="0.00000 0.00080 0.03183"/>
      <mass value="0.94658"/>
      <!-- <inertia ixx="0.00152547" ixy="0.0" ixz="0.0" iyy="0.00045954" iyz="-0.00001086" izz="0.00151740" /> -->
      <inertia ixx="0.00183005466667" ixy="0.0" ixz="0.0" iyy="0.000567948" iyz="0.0" izz="0.00183005466667"/>
    </inertial>
  </link>
  <!-- Joint 2 -->
  <joint name="rightarm_shoulder_lift_joint" type="revolute">
    <parent link="rightarm_upper_arm_link"/>
    <child link="rightarm_forearm_link"/>
    <origin rpy="0 0 0" xyz="0 0 0.033"/>
    <axis xyz="0 1 0"/>
    <limit effort="1000" lower="-1.8849555924" upper="1.8849555924" velocity="6.5"/>
    <dynamics damping="0"/>
  </joint>
  <!-- link 3 -->
  <link name="rightarm_forearm_link">
    <collision>
      <origin rpy="1.570796327 0 3.141592654" xyz="-.001 0 0.148"/>
      <geometry>
        <mesh filename="package://manipulator_description/meshes/collision/link3.stl"/>
      </geometry>
    </collision>
    <visual>
      <origin rpy="0 0 3.141592654" xyz="0 0 -0.159"/>
      <geometry>
        <mesh filename="package://manipulator_description/meshes/link_3.stl" scale="0.001 0.001 0.001"/>
      </geometry>
      <material name="grey"/>
    </visual>
    <inertial>
      <origin rpy="0 0 0" xyz="0 0 0.148"/>
      <!-- <mass value="1.404"/> -->
      <!-- <inertia ixx="1.0" ixy="0.0" ixz="0.0" iyy="1.0" iyz="0.0" izz="1.0" /> -->
      <mass value="1.30260"/>
      <!-- <inertia ixx="0.01111021" ixy="0.00001331" ixz="-0.00134208" iyy="0.01046642" iyz="0.00016235" izz="0.00202081" /> -->
      <inertia ixx="0.0136625102365" ixy="0.0" ixz="0.0" iyy="0.0124082569044" iyz="0.0" izz="0.00324753226791"/>
    </inertial>
  </link>
  <!-- Joint 3 -->
  <joint name="rightarm_elbow_joint" type="revolute">
    <parent link="rightarm_forearm_link"/>
    <child link="rightarm_wrist_1_link"/>
    <origin rpy="0 0.7853981635 0" xyz="0.03 0.0 0.264"/>
    <axis xyz="0 1 0"/>
    <limit effort="1000" lower="-1.2566370616" upper="2.26194671088" velocity="6.5"/>
    <dynamics damping="0"/>
  </joint>
  <!-- link 4 -->
  <link name="rightarm_wrist_1_link">
    <collision>
      <origin rpy="1.570796327 0 3.141592654" xyz="-0.03 0.0 0.1285"/>
      <geometry>
        <mesh filename="package://manipulator_description/meshes/collision/link4.stl"/>
      </geometry>
    </collision>
    <visual>
      <origin rpy="0 0 3.141592654" xyz="-0.03 0 -0.423"/>
      <geometry>
        <mesh filename="package://manipulator_description/meshes/link_4.stl" scale="0.001 0.001 0.001"/>
      </geometry>
      <material name="grey"/>
    </visual>
    <inertial>
      <origin rpy="0 1.570796327 0" xyz="-0.03 0 0.1285"/>
      <!-- <mass value="1.236" /> -->
      <!-- <inertia ixx="1.0" ixy="0.0" ixz="0.0" iyy="1.0" iyz="0.0" izz="1.0" /> -->
      <mass value="1.15977"/>
      <!-- <inertia ixx="0.00096726" ixy="0.00004383" ixz="-0.00002771" iyy="0.00318801" iyz="0.00000627" izz="0.00341484" /> -->
      <inertia ixx="0.00205032491251" ixy="0.0" ixz="0.0" iyy="0.00691847164616" iyz="0.0" izz="0.00765159473365"/>
    </inertial>
  </link>
  <!-- Joint 4 -->
  <joint name="rightarm_wrist_1_joint" type="revolute">
    <parent link="rightarm_wrist_1_link"/>
    <child link="rightarm_wrist_2_link"/>
    <origin rpy="0 0 0" xyz="-0.03 0.0 0.231"/>
    <axis xyz="0 0 1"/>
    <limit effort="1000" lower="-3.141592654" upper="3.141592654" velocity="6.5"/>
    <dynamics damping="0"/>
  </joint>
  <!-- link 5 -->
  <link name="rightarm_wrist_2_link">
    <collision>
      <origin rpy="0 0 3.141592654" xyz="0.0 0.0 0.024"/>
      <geometry>
        <box size="0.048 0.09 0.048"/>
      </geometry>
    </collision>
    <visual>
      <origin rpy="0 0 3.141592654" xyz="0 0 -0.654"/>
      <geometry>
        <mesh filename="package://manipulator_description/meshes/link_5.stl" scale="0.001 0.001 0.001"/>
      </geometry>
      <material name="grey"/>
    </visual>
    <inertial>
      <origin rpy="0 0 0" xyz="0 0 0.024"/>
      <!-- <mass value="0.491" /> -->
      <!-- <inertia ixx="1.0" ixy="0.0" ixz="0.0" iyy="1.0" iyz="0.0" izz="1.0" /> -->
      <mass value="0.44688"/>
      <!-- <inertia ixx="0.00030285" ixy="0.00000761" ixz="0.00000031" iyy="0.00022339" iyz="-0.00000001" izz="0.00039766" /> -->
      <inertia ixx="0.00038744496" ixy="0.0" ixz="0.0" iyy="0.00017160192" iyz="0.0" izz="0.00038744496"/>
    </inertial>
  </link>
  <!-- Joint 5 -->
  <joint name="rightarm_wrist_2_joint" type="revolute">
    <parent link="rightarm_wrist_2_link"/>
    <child link="rightarm_wrist_3_link"/>
    <origin rpy="0 0 0" xyz="0.0 0.0 0.027"/>
    <axis xyz="0 1 0"/>
    <limit effort="1000" lower="-1.570796327" upper="1.570796327" velocity="6.5"/>
    <dynamics damping="0"/>
  </joint>
  <!-- link 6 -->
  <link name="rightarm_wrist_3_link">
    <collision>
      <origin rpy="1.570796327 0 1.570796327" xyz="0.0 0.0 0.081"/>
      <geometry>
        <mesh filename="package://manipulator_description/meshes/collision/link6.stl"/>
      </geometry>
    </collision>
    <visual>
      <origin rpy="0 0 3.141592654" xyz="0 0 -0.681"/>
      <geometry>
        <mesh filename="package://manipulator_description/meshes/link_6.stl" scale="0.001 0.001 0.001"/>
      </geometry>
      <material name="grey"/>
    </visual>
    <inertial>
      <origin rpy="1.570796327 1.570796327 0" xyz="0 0 0.081"/>
      <!-- <mass value="0.454" /> -->
      <!-- <inertia ixx="1.0" ixy="0.0" ixz="0.0" iyy="1.0" iyz="0.0" izz="1.0" /> -->
      <mass value="0.43273"/>
      <!-- <inertia ixx="0.00021512" ixy="0.00001009" ixz="0.00000000" iyy="0.00042827" iyz="0.00000000" izz="0.00051436" /> -->
      <inertia ixx="0.00039594795" ixy="0.0" ixz="0.0" iyy="0.00104401581334" iyz="0.0" izz="0.000775290483338"/>
    </inertial>
  </link>
  <!-- Joint 6 -->
  <joint name="rightarm_wrist_3_joint" type="revolute">
    <parent link="rightarm_wrist_3_link"/>
    <child link="rightarm_ee_link"/>
    <origin rpy="0 0 0" xyz="0.0 0.0 0.123"/>
    <axis xyz="0 0 1"/>
    <limit effort="1000" lower="-3.141592654" upper="3.141592654" velocity="6.5"/>
    <dynamics damping="0"/>
  </joint>
  <!-- End Effector -->
  <link name="rightarm_ee_link">
  </link>
  <transmission name="rightarm_shoulder_pan_trans">
    <type>transmission_interface/SimpleTransmission</type>
    <joint name="rightarm_shoulder_pan_joint">
      <hardwareInterface>EffortJointInterface</hardwareInterface>
    </joint>
    <actuator name="rightarm_shoulder_pan_motor">
      <hardwareInterface>EffortJointInterface</hardwareInterface>
      <mechanicalReduction>1</mechanicalReduction>
    </actuator>
  </transmission>
  <transmission name="rightarm_shoulder_lift_trans">
    <type>transmission_interface/SimpleTransmission</type>
    <joint name="rightarm_shoulder_lift_joint">
      <hardwareInterface>EffortJointInterface</hardwareInterface>
    </joint>
    <actuator name="rightarm_shoulder_lift_motor">
      <hardwareInterface>EffortJointInterface</hardwareInterface>
      <mechanicalReduction>1</mechanicalReduction>
    </actuator>
  </transmission>
  <transmission name="rightarm_elbow_trans">
    <type>transmission_interface/SimpleTransmission</type>
    <joint name="rightarm_elbow_joint">
      <hardwareInterface>EffortJointInterface</hardwareInterface>
    </joint>
    <actuator name="rightarm_elbow_motor">
      <hardwareInterface>EffortJointInterface</hardwareInterface>
      <mechanicalReduction>1</mechanicalReduction>
    </actuator>
  </transmission>
  <transmission name="rightarm_wrist_1_trans">
    <type>transmission_interface/SimpleTransmission</type>
    <joint name="rightarm_wrist_1_joint">
      <hardwareInterface>EffortJointInterface</hardwareInterface>
    </joint>
    <actuator name="rightarm_wrist_1_motor">
      <hardwareInterface>EffortJointInterface</hardwareInterface>
      <mechanicalReduction>1</mechanicalReduction>
    </actuator>
  </transmission>
  <transmission name="rightarm_wrist_2_trans">
    <type>transmission_interface/SimpleTransmission</type>
    <joint name="rightarm_wrist_2_joint">
      <hardwareInterface>EffortJointInterface</hardwareInterface>
    </joint>
    <actuator name="rightarm_wrist_2_motor">
      <hardwareInterface>EffortJointInterface</hardwareInterface>
      <mechanicalReduction>1</mechanicalReduction>
    </actuator>
  </transmission>
  <transmission name="rightarm_wrist_3_trans">
    <type>transmission_interface/SimpleTransmission</type>
    <joint name="rightarm_wrist_3_joint">
      <hardwareInterface>EffortJointInterface</hardwareInterface>
    </joint>
    <actuator name="rightarm_wrist_3_motor">
      <hardwareInterface>EffortJointInterface</hardwareInterface>
      <mechanicalReduction>1</mechanicalReduction>
    </actuator>
  </transmission>
  <joint name="rightarm_ee_link_rightarm_base_joint" type="fixed">
    <origin rpy="0 0 0" xyz="0 0 0"/>
    <parent link="rightarm_ee_link"/>
    <child link="rightarm_finger_link"/>
  </joint>
  <link name="rightarm_finger_link">
    <visual>
      <origin rpy="1.570796327 0 0" xyz="0 0 0"/>
      <geometry>
        <mesh filename="package://bbbot_description/meshes/visual/finger.stl"/>
      </geometry>
      <material name="white"/>
    </visual>
    <!-- Need better collision model -->
    <collision>
      <origin rpy="1.570796327 0 1.570796327" xyz="0 0 0"/>
      <geometry>
        <mesh filename="package://bbbot_description/meshes/collision/finger.stl"/>
      </geometry>
      <!-- <origin xyz="0 0 0" rpy="${pi/2} 0 0"/>
        <geometry>
          <mesh filename="package://bbbot_description/meshes/visual/finger.stl" />
        </geometry> -->
    </collision>
    <!-- <inertial>
        <origin xyz="0 0 0" rpy="0 0 0"/>
        <mass value="0.250"/>
        <inertia ixx="0.0" ixy="0.0" ixz="0.0" iyy="0.0" iyz="0.0" izz="0.0"/>
      </inertial> -->
    <inertial>
      <origin rpy="0 0 0" xyz="0 0 0.05"/>
      <mass value="0.3"/>
      <inertia ixx="0.0008125" ixy="0" ixz="0" iyy="0.001125" iyz="0" izz="0.001125"/>
    </inertial>
  </link>
  <joint name="world_stand" type="fixed">
    <parent link="world"/>
    <child link="base_link"/>
    <origin rpy="0 0 0" xyz="0 0 0"/>
  </joint>
</robot>
