<?xml version="1.0"?>
<robot xmlns:xacro="http://www.ros.org/wiki/xacro">

  <xacro:include filename="$(find manipulator_description)/urdf/transmission.xacro" />
  <!-- <xacro:include filename="$(find manipulator_description)/urdf/robotis_manipulator_h.gazebo" /> -->
  <xacro:include filename="$(find manipulator_description)/urdf/materials.xacro" />

  <xacro:property name="pi" value="3.141592654" />
  <xacro:property name="prefix_val" value="" />

  <xacro:macro name="manipulator_h_arm" params="prefix joint_limited parent dummy_ee_link:=false *origin">

    <!-- Suffix prefix with underscore -->
    <xacro:if value="${prefix.__len__()}">
      <xacro:property name="prefix_val" value="${prefix + '_'}" />
    </xacro:if>

    <!-- First element of the arm fixed to the parent -->
    <joint name="${parent}_${prefix_val}_base_joint" type="fixed">
      <xacro:insert_block name="origin" />
      <parent link="${parent}" />
      <child link="${prefix_val}shoulder_link" />
    </joint>

    <!-- link 1 -->
    <link name="${prefix_val}shoulder_link">
      <collision>
        <origin xyz="0 0 0.063" rpy="0 0 ${pi}"/>
        <geometry>
          <box size="0.054 0.054 0.126"/>
        </geometry>
      </collision>
      <visual>
        <origin xyz="0 0 0" rpy="0 0 ${pi}"/>
        <geometry>
          <mesh filename="package://manipulator_description/meshes/link_1.stl" scale="0.001 0.001 0.001"/>
        </geometry>
        <material name="grey"/>
      </visual>

      <inertial>
        <!-- <origin xyz="0 0 0" rpy="0 0 0"/> -->
        <!-- <mass value="0.936"/> -->
        <!-- <inertia ixx="1.0" ixy="0.0" ixz="0.0" iyy="1.0" iyz="0.0" izz="1.0" /> -->
        <origin xyz="0.00023 0.00000 0.06223" rpy="0 0 0"/>
        <mass value="0.85644"/>
        <!-- <inertia ixx="0.00121064" ixy="0.0" ixz="0.00001100" iyy="0.00120886" iyz="0.0" izz="0.00038103" /> -->
        <inertia ixx="0.00134118504" ixy="0.0" ixz="0.0" iyy="0.00134118504" iyz="0.0" izz="0.00041622984" />
      </inertial>
    </link>

    <!-- Joint 1 -->
    <joint name="${prefix_val}shoulder_pan_joint" type="revolute">
      <parent link="${prefix_val}shoulder_link" />
      <child link="${prefix_val}upper_arm_link" />
      <origin xyz="0 0 0.126" rpy="0 0 0"/>
      <axis xyz="0 0 1"/>
      <limit velocity="6.5" effort="1000" lower="${-pi*0.95}" upper="${pi*0.95}" />
      <dynamics damping="0"/>
    </joint>

    <!-- link 2 -->
    <link name="${prefix_val}upper_arm_link">
      <collision>
        <origin xyz="0 0 0.03" rpy="0 0 ${pi}"/>
        <geometry>
          <box size="0.06 0.14 0.06"/>
        </geometry>
      </collision>

      <visual>
        <origin xyz="0 0 -0.126" rpy="0 0 ${pi}"/>
        <geometry>
          <mesh filename="package://manipulator_description/meshes/link_2.stl" scale="0.001 0.001 0.001"/>
        </geometry>
        <material name="grey"/>
      </visual>

      <inertial>
        <!-- <origin xyz="0 0 0" rpy="0 0 0"/> -->
        <!-- <mass value="1.030"/> -->
        <!-- <inertia ixx="1.0" ixy="0.0" ixz="0.0" iyy="1.0" iyz="0.0" izz="1.0" /> -->
        <origin xyz="0.00000 0.00080 0.03183" rpy="0 0 0"/>
        <mass value="0.94658"/>
        <!-- <inertia ixx="0.00152547" ixy="0.0" ixz="0.0" iyy="0.00045954" iyz="-0.00001086" izz="0.00151740" /> -->
        <inertia ixx="0.00183005466667" ixy="0.0" ixz="0.0" iyy="0.000567948" iyz="0.0" izz="0.00183005466667" />
      </inertial>
    </link>

    <!-- Joint 2 -->
    <joint name="${prefix_val}shoulder_lift_joint" type="revolute">
      <parent link="${prefix_val}upper_arm_link" />
      <child link="${prefix_val}forearm_link" />
      <origin xyz="0 0 0.033" rpy="0 0 0"/>
      <axis xyz="0 1 0"/>
      <limit velocity="6.5" effort="1000" lower="${-pi*0.6}" upper="${pi*0.6}" />
      <dynamics damping="0"/>
    </joint>

    <!-- link 3 -->
    <link name="${prefix_val}forearm_link">
      <collision>
        <origin xyz="-.001 0 0.148" rpy="${pi/2} 0 ${pi}"/>
        <geometry>
          <mesh filename="package://manipulator_description/meshes/collision/link3.stl"/>
        </geometry>
      </collision>

      <visual>
        <origin xyz="0 0 -0.159" rpy="0 0 ${pi}"/>
        <geometry>
          <mesh filename="package://manipulator_description/meshes/link_3.stl" scale="0.001 0.001 0.001"/>
        </geometry>
        <material name="grey"/>
      </visual>

      <inertial>
        <origin xyz="0 0 0.148" rpy="0 0 0"/>
        <!-- <mass value="1.404"/> -->
        <!-- <inertia ixx="1.0" ixy="0.0" ixz="0.0" iyy="1.0" iyz="0.0" izz="1.0" /> -->
        <mass value="1.30260"/>
        <!-- <inertia ixx="0.01111021" ixy="0.00001331" ixz="-0.00134208" iyy="0.01046642" iyz="0.00016235" izz="0.00202081" /> -->
        <inertia ixx="0.0136625102365" ixy="0.0" ixz="0.0" iyy="0.0124082569044" iyz="0.0" izz="0.00324753226791" />
      </inertial>
    </link>

    <!-- Joint 3 -->
    <joint name="${prefix_val}elbow_joint" type="revolute">
      <parent link="${prefix_val}forearm_link" />
      <child link="${prefix_val}wrist_1_link" />
      <origin xyz="0.03 0.0 0.264" rpy="0 ${45.0*pi/180.0} 0" />
      <axis xyz="0 1 0"/>
      <limit velocity="6.5" effort="1000" lower="${-pi*0.4}" upper="${pi*0.72}" />
      <dynamics damping="0"/>
    </joint>

    <!-- link 4 -->
    <link name="${prefix_val}wrist_1_link">
      <collision>
        <origin xyz="-0.03 0.0 0.1285" rpy="${pi/2} 0 ${pi}" />
        <geometry>
          <mesh filename="package://manipulator_description/meshes/collision/link4.stl"/>
        </geometry>
      </collision>

      <visual>
        <origin xyz="-0.03 0 -0.423" rpy="0 0 ${pi}" />
        <geometry>
          <mesh filename="package://manipulator_description/meshes/link_4.stl" scale="0.001 0.001 0.001"/>
        </geometry>
        <material name="grey"/>
      </visual>

      <inertial>
        <origin xyz="-0.03 0 0.1285" rpy="0 ${pi/2} 0" />
        <!-- <mass value="1.236" /> -->
        <!-- <inertia ixx="1.0" ixy="0.0" ixz="0.0" iyy="1.0" iyz="0.0" izz="1.0" /> -->
        <mass value="1.15977"/>
        <!-- <inertia ixx="0.00096726" ixy="0.00004383" ixz="-0.00002771" iyy="0.00318801" iyz="0.00000627" izz="0.00341484" /> -->
        <inertia ixx="0.00205032491251" ixy="0.0" ixz="0.0" iyy="0.00691847164616" iyz="0.0" izz="0.00765159473365" />
      </inertial>
    </link>

    <!-- Joint 4 -->
    <joint name="${prefix_val}wrist_1_joint" type="revolute">
      <parent link="${prefix_val}wrist_1_link" />
      <child link="${prefix_val}wrist_2_link" />
      <origin xyz="-0.03 0.0 0.231" rpy="0 0 0" />
      <axis xyz="0 0 1" />
      <limit velocity="6.5" effort="1000" lower="${-pi}" upper="${pi}" />
      <dynamics damping="0"/>
    </joint>

    <!-- link 5 -->
    <link name="${prefix_val}wrist_2_link">
      <collision>
        <origin xyz="0.0 0.0 0.024" rpy="0 0 ${pi}" />
        <geometry>
          <box size="0.048 0.09 0.048" />
        </geometry>
      </collision>

      <visual>
        <origin xyz="0 0 -0.654" rpy="0 0 ${pi}" />
        <geometry>
          <mesh filename="package://manipulator_description/meshes/link_5.stl" scale="0.001 0.001 0.001"/>
        </geometry>
        <material name="grey"/>
      </visual>

      <inertial>
        <origin xyz="0 0 0.024" rpy="0 0 0" />
        <!-- <mass value="0.491" /> -->
        <!-- <inertia ixx="1.0" ixy="0.0" ixz="0.0" iyy="1.0" iyz="0.0" izz="1.0" /> -->
        <mass value="0.44688"/>
        <!-- <inertia ixx="0.00030285" ixy="0.00000761" ixz="0.00000031" iyy="0.00022339" iyz="-0.00000001" izz="0.00039766" /> -->
        <inertia ixx="0.00038744496" ixy="0.0" ixz="0.0" iyy="0.00017160192" iyz="0.0" izz="0.00038744496" />
      </inertial>
    </link>

    <!-- Joint 5 -->
    <joint name="${prefix_val}wrist_2_joint" type="revolute">
      <parent link="${prefix_val}wrist_2_link" />
      <child link="${prefix_val}wrist_3_link" />
      <origin xyz="0.0 0.0 0.027" rpy="0 0 0" />
      <axis xyz="0 1 0" />
      <limit velocity="6.5" effort="1000" lower="${-pi*0.5}" upper="${pi*0.5}" />
      <dynamics damping="0"/>
    </joint>

    <!-- link 6 -->
    <link name="${prefix_val}wrist_3_link">
      <collision>
        <origin xyz="0.0 0.0 0.081" rpy="${pi/2} 0 ${pi/2}" />
        <geometry>
          <mesh filename="package://manipulator_description/meshes/collision/link6.stl"/>
        </geometry>
      </collision>

      <visual>
        <origin xyz="0 0 -0.681" rpy="0 0 ${pi}" />
        <geometry>
          <mesh filename="package://manipulator_description/meshes/link_6.stl" scale="0.001 0.001 0.001"/>
        </geometry>
        <material name="grey"/>
      </visual>

      <inertial>
        <origin xyz="0 0 0.081" rpy="${pi/2} ${pi/2} 0" />
        <!-- <mass value="0.454" /> -->
        <!-- <inertia ixx="1.0" ixy="0.0" ixz="0.0" iyy="1.0" iyz="0.0" izz="1.0" /> -->
        <mass value="0.43273"/>
        <!-- <inertia ixx="0.00021512" ixy="0.00001009" ixz="0.00000000" iyy="0.00042827" iyz="0.00000000" izz="0.00051436" /> -->
        <inertia ixx="0.00039594795" ixy="0.0" ixz="0.0" iyy="0.00104401581334" iyz="0.0" izz="0.000775290483338" />
      </inertial>
    </link>

    <!-- Joint 6 -->
    <joint name="${prefix_val}wrist_3_joint" type="revolute">
      <parent link="${prefix_val}wrist_3_link" />
      <child link="${prefix_val}ee_link" />
      <origin xyz="0.0 0.0 0.123" rpy="0 0 0" />
      <axis xyz="0 0 1" />
      <limit velocity="6.5" effort="1000" lower="${-pi}" upper="${pi}" />
      <dynamics damping="0"/>
    </joint>

    <!-- End Effector -->
    <link name="${prefix_val}ee_link">
      <xacro:unless value="${dummy_ee_link}">
        <collision>
          <origin xyz="0.0 0.0 0.025" rpy="0 0 0" />
          <geometry>
            <box size="0.05 0.05 0.05"/>
          </geometry>
        </collision>

        <visual>
          <origin xyz="0.0 0.0 0.025" rpy="0 0 0" />
          <geometry>
            <box size="0.05 0.05 0.05"/>
          </geometry>
          <material name="red"/>
        </visual>
        <inertial>
          <origin xyz="0 0 0" rpy="0 0 0"/>
          <mass value="0.1" />
          <inertia ixx="0.0000416666666667" ixy="0.0" ixz="0.0" iyy="0.0000416666666667" iyz="0.0" izz="0.0000416666666667" />
        </inertial>
          <!-- <inertia ixx="0.0000016666" ixy="0.0" ixz="0.0" iyy="0.0000016666" iyz="0.0" izz="0.0000016666" /> -->
        <!-- <inertial>
          <origin xyz="0 0 0" rpy="0 0 0"/> -->
          <!-- <mass value="0.001" /> -->
          <!-- <inertia ixx="1.0" ixy="0.0" ixz="0.0" iyy="1.0" iyz="0.0" izz="1.0" /> -->
          <!-- <mass value="0.01919"/> -->
          <!-- <inertia ixx="0.00000938" ixy="0.0" ixz="0.0" iyy="0.00000338" iyz="0.0" izz="0.00000635" /> -->
          <!-- <inertia ixx="0.0000011983" ixy="0.0" ixz="0.0" iyy="0.0000011983" iyz="0.0" izz="0.0000011983" />
        </inertial> -->
      </xacro:unless>
    </link>

    <xacro:manipulator_arm_transmission prefix="${prefix_val}" />
  </xacro:macro>
</robot>
